from __future__ import print_function # Python 2/3 compatibility
# The following two lines are a fix for Windows boto3 issue
import os
os.environ["TZ"]="UTC"
import boto3
import sys

dynamodb = boto3.resource('dynamodb', region_name='us-west-2', endpoint_url="http://localhost:8000")

try:
    table = dynamodb.create_table(
    TableName='Movies',
    KeySchema=[
        {
            'AttributeName': 'year',
            'KeyType': 'HASH'  #Partition key
        },
        {
            'AttributeName': 'title',
            'KeyType': 'RANGE'  #Sort key
        }
    ],
    AttributeDefinitions=[
        {
            'AttributeName': 'year',
            'AttributeType': 'N'
        },
        {
            'AttributeName': 'title',
            'AttributeType': 'S'
        },

    ],
    ProvisionedThroughput={
        'ReadCapacityUnits': 1,
        'WriteCapacityUnits': 1
    }
)
    print("table created")

except OSError as err:
    print("OS error: {0}".format(err))
except ValueError:
    print("Could not convert data to an integer.")
except:
    print("Unexpected error:", sys.exc_info()[0])
    raise